2024-01-16 14:46:37,628 ERROR: Exception on /api/users/1/post [GET] [in /Users/thanhvy/Documents/microblog/venv/lib/python3.12/site-packages/flask/app.py:1414]
Traceback (most recent call last):
  File "/Users/thanhvy/Documents/microblog/venv/lib/python3.12/site-packages/flask/app.py", line 2190, in wsgi_app
    response = self.full_dispatch_request()
               ^^^^^^^^^^^^^^^^^^^^^^^^^^^^
  File "/Users/thanhvy/Documents/microblog/venv/lib/python3.12/site-packages/flask/app.py", line 1486, in full_dispatch_request
    rv = self.handle_user_exception(e)
         ^^^^^^^^^^^^^^^^^^^^^^^^^^^^^
  File "/Users/thanhvy/Documents/microblog/venv/lib/python3.12/site-packages/flask/app.py", line 1484, in full_dispatch_request
    rv = self.dispatch_request()
         ^^^^^^^^^^^^^^^^^^^^^^^
  File "/Users/thanhvy/Documents/microblog/venv/lib/python3.12/site-packages/flask/app.py", line 1469, in dispatch_request
    return self.ensure_sync(self.view_functions[rule.endpoint])(**view_args)
           ^^^^^^^^^^^^^^^^^^^^^^^^^^^^^^^^^^^^^^^^^^^^^^^^^^^^^^^^^^^^^^^^^
  File "/Users/thanhvy/Documents/microblog/venv/lib/python3.12/site-packages/flask_httpauth.py", line 174, in decorated
    return self.ensure_sync(f)(*args, **kwargs)
           ^^^^^^^^^^^^^^^^^^^^^^^^^^^^^^^^^^^^
  File "/Users/thanhvy/Documents/microblog/app/api/users.py", line 89, in get_post
    return User.to_collection_dict(post.posts.select(), page, per_page,
                                   ^^^^^^^^^^
AttributeError: 'Post' object has no attribute 'posts'
2024-01-16 14:47:04,381 INFO: Microblog startup [in /Users/thanhvy/Documents/microblog/app/__init__.py:90]
2024-01-16 14:47:11,634 ERROR: Exception on /api/users/1/post [GET] [in /Users/thanhvy/Documents/microblog/venv/lib/python3.12/site-packages/flask/app.py:1414]
Traceback (most recent call last):
  File "/Users/thanhvy/Documents/microblog/venv/lib/python3.12/site-packages/flask/app.py", line 2190, in wsgi_app
    response = self.full_dispatch_request()
               ^^^^^^^^^^^^^^^^^^^^^^^^^^^^
  File "/Users/thanhvy/Documents/microblog/venv/lib/python3.12/site-packages/flask/app.py", line 1486, in full_dispatch_request
    rv = self.handle_user_exception(e)
         ^^^^^^^^^^^^^^^^^^^^^^^^^^^^^
  File "/Users/thanhvy/Documents/microblog/venv/lib/python3.12/site-packages/flask/app.py", line 1484, in full_dispatch_request
    rv = self.dispatch_request()
         ^^^^^^^^^^^^^^^^^^^^^^^
  File "/Users/thanhvy/Documents/microblog/venv/lib/python3.12/site-packages/flask/app.py", line 1469, in dispatch_request
    return self.ensure_sync(self.view_functions[rule.endpoint])(**view_args)
           ^^^^^^^^^^^^^^^^^^^^^^^^^^^^^^^^^^^^^^^^^^^^^^^^^^^^^^^^^^^^^^^^^
  File "/Users/thanhvy/Documents/microblog/venv/lib/python3.12/site-packages/flask_httpauth.py", line 174, in decorated
    return self.ensure_sync(f)(*args, **kwargs)
           ^^^^^^^^^^^^^^^^^^^^^^^^^^^^^^^^^^^^
  File "/Users/thanhvy/Documents/microblog/app/api/users.py", line 89, in get_post
    return User.to_collection_dict(post.body.select(), page, per_page,
                                   ^^^^^^^^^^^^^^^^
AttributeError: 'str' object has no attribute 'select'
2024-01-16 14:51:07,492 INFO: Microblog startup [in /Users/thanhvy/Documents/microblog/app/__init__.py:90]
2024-01-16 14:51:14,364 ERROR: Exception on /api/users/1/post [GET] [in /Users/thanhvy/Documents/microblog/venv/lib/python3.12/site-packages/flask/app.py:1414]
Traceback (most recent call last):
  File "/Users/thanhvy/Documents/microblog/venv/lib/python3.12/site-packages/flask/app.py", line 2190, in wsgi_app
    response = self.full_dispatch_request()
               ^^^^^^^^^^^^^^^^^^^^^^^^^^^^
  File "/Users/thanhvy/Documents/microblog/venv/lib/python3.12/site-packages/flask/app.py", line 1486, in full_dispatch_request
    rv = self.handle_user_exception(e)
         ^^^^^^^^^^^^^^^^^^^^^^^^^^^^^
  File "/Users/thanhvy/Documents/microblog/venv/lib/python3.12/site-packages/flask/app.py", line 1484, in full_dispatch_request
    rv = self.dispatch_request()
         ^^^^^^^^^^^^^^^^^^^^^^^
  File "/Users/thanhvy/Documents/microblog/venv/lib/python3.12/site-packages/flask/app.py", line 1469, in dispatch_request
    return self.ensure_sync(self.view_functions[rule.endpoint])(**view_args)
           ^^^^^^^^^^^^^^^^^^^^^^^^^^^^^^^^^^^^^^^^^^^^^^^^^^^^^^^^^^^^^^^^^
  File "/Users/thanhvy/Documents/microblog/venv/lib/python3.12/site-packages/flask_httpauth.py", line 174, in decorated
    return self.ensure_sync(f)(*args, **kwargs)
           ^^^^^^^^^^^^^^^^^^^^^^^^^^^^^^^^^^^^
  File "/Users/thanhvy/Documents/microblog/app/api/users.py", line 89, in get_post
    return User.to_collection_dict(post.select(), page, per_page,
                                   ^^^^^^^^^^^
AttributeError: 'Post' object has no attribute 'select'
2024-01-16 14:52:58,179 INFO: Microblog startup [in /Users/thanhvy/Documents/microblog/app/__init__.py:90]
2024-01-16 14:53:09,337 ERROR: Exception on /api/users/1/post [GET] [in /Users/thanhvy/Documents/microblog/venv/lib/python3.12/site-packages/flask/app.py:1414]
Traceback (most recent call last):
  File "/Users/thanhvy/Documents/microblog/venv/lib/python3.12/site-packages/flask/app.py", line 2190, in wsgi_app
    response = self.full_dispatch_request()
               ^^^^^^^^^^^^^^^^^^^^^^^^^^^^
  File "/Users/thanhvy/Documents/microblog/venv/lib/python3.12/site-packages/flask/app.py", line 1486, in full_dispatch_request
    rv = self.handle_user_exception(e)
         ^^^^^^^^^^^^^^^^^^^^^^^^^^^^^
  File "/Users/thanhvy/Documents/microblog/venv/lib/python3.12/site-packages/flask/app.py", line 1484, in full_dispatch_request
    rv = self.dispatch_request()
         ^^^^^^^^^^^^^^^^^^^^^^^
  File "/Users/thanhvy/Documents/microblog/venv/lib/python3.12/site-packages/flask/app.py", line 1469, in dispatch_request
    return self.ensure_sync(self.view_functions[rule.endpoint])(**view_args)
           ^^^^^^^^^^^^^^^^^^^^^^^^^^^^^^^^^^^^^^^^^^^^^^^^^^^^^^^^^^^^^^^^^
  File "/Users/thanhvy/Documents/microblog/venv/lib/python3.12/site-packages/flask_httpauth.py", line 174, in decorated
    return self.ensure_sync(f)(*args, **kwargs)
           ^^^^^^^^^^^^^^^^^^^^^^^^^^^^^^^^^^^^
  File "/Users/thanhvy/Documents/microblog/app/api/users.py", line 89, in get_post
    return User.to_collection_dict(sa.select(Post).where(user_id=id), page, per_page,
                                   ^^^^^^^^^^^^^^^^^^^^^^^^^^^^^^^^^
TypeError: Select.where() got an unexpected keyword argument 'user_id'
2024-01-16 14:53:49,398 INFO: Microblog startup [in /Users/thanhvy/Documents/microblog/app/__init__.py:90]
2024-01-16 14:53:55,230 ERROR: Exception on /api/users/1/post [GET] [in /Users/thanhvy/Documents/microblog/venv/lib/python3.12/site-packages/flask/app.py:1414]
Traceback (most recent call last):
  File "/Users/thanhvy/Documents/microblog/venv/lib/python3.12/site-packages/flask/app.py", line 2190, in wsgi_app
    response = self.full_dispatch_request()
               ^^^^^^^^^^^^^^^^^^^^^^^^^^^^
  File "/Users/thanhvy/Documents/microblog/venv/lib/python3.12/site-packages/flask/app.py", line 1486, in full_dispatch_request
    rv = self.handle_user_exception(e)
         ^^^^^^^^^^^^^^^^^^^^^^^^^^^^^
  File "/Users/thanhvy/Documents/microblog/venv/lib/python3.12/site-packages/flask/app.py", line 1484, in full_dispatch_request
    rv = self.dispatch_request()
         ^^^^^^^^^^^^^^^^^^^^^^^
  File "/Users/thanhvy/Documents/microblog/venv/lib/python3.12/site-packages/flask/app.py", line 1469, in dispatch_request
    return self.ensure_sync(self.view_functions[rule.endpoint])(**view_args)
           ^^^^^^^^^^^^^^^^^^^^^^^^^^^^^^^^^^^^^^^^^^^^^^^^^^^^^^^^^^^^^^^^^
  File "/Users/thanhvy/Documents/microblog/venv/lib/python3.12/site-packages/flask_httpauth.py", line 174, in decorated
    return self.ensure_sync(f)(*args, **kwargs)
           ^^^^^^^^^^^^^^^^^^^^^^^^^^^^^^^^^^^^
  File "/Users/thanhvy/Documents/microblog/app/api/users.py", line 89, in get_post
    return User.to_collection_dict(sa.select(Post).where(Post.user_id==id), page, per_page,
           ^^^^^^^^^^^^^^^^^^^^^^^^^^^^^^^^^^^^^^^^^^^^^^^^^^^^^^^^^^^^^^^^^^^^^^^^^^^^^^^^
  File "/Users/thanhvy/Documents/microblog/app/models.py", line 82, in to_collection_dict
    'items': [item.to_dict() for item in resources.items],
              ^^^^^^^^^^^^
AttributeError: 'Post' object has no attribute 'to_dict'
2024-01-16 14:54:33,561 INFO: Microblog startup [in /Users/thanhvy/Documents/microblog/app/__init__.py:90]
