2024-01-16 11:30:02,286 ERROR: Exception on /api/users/1 [GET] [in /Users/thanhvy/Documents/microblog/venv/lib/python3.12/site-packages/flask/app.py:1414]
Traceback (most recent call last):
  File "/Users/thanhvy/Documents/microblog/venv/lib/python3.12/site-packages/flask/app.py", line 2190, in wsgi_app
    response = self.full_dispatch_request()
               ^^^^^^^^^^^^^^^^^^^^^^^^^^^^
  File "/Users/thanhvy/Documents/microblog/venv/lib/python3.12/site-packages/flask/app.py", line 1486, in full_dispatch_request
    rv = self.handle_user_exception(e)
         ^^^^^^^^^^^^^^^^^^^^^^^^^^^^^
  File "/Users/thanhvy/Documents/microblog/venv/lib/python3.12/site-packages/flask/app.py", line 1484, in full_dispatch_request
    rv = self.dispatch_request()
         ^^^^^^^^^^^^^^^^^^^^^^^
  File "/Users/thanhvy/Documents/microblog/venv/lib/python3.12/site-packages/flask/app.py", line 1469, in dispatch_request
    return self.ensure_sync(self.view_functions[rule.endpoint])(**view_args)
           ^^^^^^^^^^^^^^^^^^^^^^^^^^^^^^^^^^^^^^^^^^^^^^^^^^^^^^^^^^^^^^^^^
  File "/Users/thanhvy/Documents/microblog/venv/lib/python3.12/site-packages/flask_httpauth.py", line 174, in decorated
    return self.ensure_sync(f)(*args, **kwargs)
           ^^^^^^^^^^^^^^^^^^^^^^^^^^^^^^^^^^^^
  File "/Users/thanhvy/Documents/microblog/app/api/users.py", line 12, in get_user
    return db.get_or_404(User, id).to_dict()
           ^^^^^^^^^^^^^^^^^^^^^^^^^^^^^^^^^
  File "/Users/thanhvy/Documents/microblog/app/models.py", line 268, in to_dict
    'post': url_for('api.get_post', id=self.id),
            ^^^^^^^^^^^^^^^^^^^^^^^^^^^^^^^^^^^
  File "/Users/thanhvy/Documents/microblog/venv/lib/python3.12/site-packages/flask/helpers.py", line 225, in url_for
    return current_app.url_for(
           ^^^^^^^^^^^^^^^^^^^^
  File "/Users/thanhvy/Documents/microblog/venv/lib/python3.12/site-packages/flask/app.py", line 1697, in url_for
    return self.handle_url_build_error(error, endpoint, values)
           ^^^^^^^^^^^^^^^^^^^^^^^^^^^^^^^^^^^^^^^^^^^^^^^^^^^^
  File "/Users/thanhvy/Documents/microblog/venv/lib/python3.12/site-packages/flask/app.py", line 1686, in url_for
    rv = url_adapter.build(  # type: ignore[union-attr]
         ^^^^^^^^^^^^^^^^^^^^^^^^^^^^^^^^^^^^^^^^^^^^^^
  File "/Users/thanhvy/Documents/microblog/venv/lib/python3.12/site-packages/werkzeug/routing/map.py", line 950, in build
    raise BuildError(endpoint, values, method, self)
werkzeug.routing.exceptions.BuildError: Could not build url for endpoint 'api.get_post' with values ['id']. Did you mean 'api.get_user' instead?
2024-01-16 11:30:27,060 ERROR: Exception on /api/users/1 [GET] [in /Users/thanhvy/Documents/microblog/venv/lib/python3.12/site-packages/flask/app.py:1414]
Traceback (most recent call last):
  File "/Users/thanhvy/Documents/microblog/venv/lib/python3.12/site-packages/flask/app.py", line 2190, in wsgi_app
    response = self.full_dispatch_request()
               ^^^^^^^^^^^^^^^^^^^^^^^^^^^^
  File "/Users/thanhvy/Documents/microblog/venv/lib/python3.12/site-packages/flask/app.py", line 1486, in full_dispatch_request
    rv = self.handle_user_exception(e)
         ^^^^^^^^^^^^^^^^^^^^^^^^^^^^^
  File "/Users/thanhvy/Documents/microblog/venv/lib/python3.12/site-packages/flask/app.py", line 1484, in full_dispatch_request
    rv = self.dispatch_request()
         ^^^^^^^^^^^^^^^^^^^^^^^
  File "/Users/thanhvy/Documents/microblog/venv/lib/python3.12/site-packages/flask/app.py", line 1469, in dispatch_request
    return self.ensure_sync(self.view_functions[rule.endpoint])(**view_args)
           ^^^^^^^^^^^^^^^^^^^^^^^^^^^^^^^^^^^^^^^^^^^^^^^^^^^^^^^^^^^^^^^^^
  File "/Users/thanhvy/Documents/microblog/venv/lib/python3.12/site-packages/flask_httpauth.py", line 174, in decorated
    return self.ensure_sync(f)(*args, **kwargs)
           ^^^^^^^^^^^^^^^^^^^^^^^^^^^^^^^^^^^^
  File "/Users/thanhvy/Documents/microblog/app/api/users.py", line 12, in get_user
    return db.get_or_404(User, id).to_dict()
           ^^^^^^^^^^^^^^^^^^^^^^^^^^^^^^^^^
  File "/Users/thanhvy/Documents/microblog/app/models.py", line 268, in to_dict
    'post': url_for('api.get_post', id=self.id),
            ^^^^^^^^^^^^^^^^^^^^^^^^^^^^^^^^^^^
  File "/Users/thanhvy/Documents/microblog/venv/lib/python3.12/site-packages/flask/helpers.py", line 225, in url_for
    return current_app.url_for(
           ^^^^^^^^^^^^^^^^^^^^
  File "/Users/thanhvy/Documents/microblog/venv/lib/python3.12/site-packages/flask/app.py", line 1697, in url_for
    return self.handle_url_build_error(error, endpoint, values)
           ^^^^^^^^^^^^^^^^^^^^^^^^^^^^^^^^^^^^^^^^^^^^^^^^^^^^
  File "/Users/thanhvy/Documents/microblog/venv/lib/python3.12/site-packages/flask/app.py", line 1686, in url_for
    rv = url_adapter.build(  # type: ignore[union-attr]
         ^^^^^^^^^^^^^^^^^^^^^^^^^^^^^^^^^^^^^^^^^^^^^^
  File "/Users/thanhvy/Documents/microblog/venv/lib/python3.12/site-packages/werkzeug/routing/map.py", line 950, in build
    raise BuildError(endpoint, values, method, self)
werkzeug.routing.exceptions.BuildError: Could not build url for endpoint 'api.get_post' with values ['id']. Did you mean 'api.get_user' instead?
2024-01-16 11:30:36,172 INFO: Microblog startup [in /Users/thanhvy/Documents/microblog/app/__init__.py:90]
2024-01-16 11:30:43,215 ERROR: Exception on /api/users/1 [GET] [in /Users/thanhvy/Documents/microblog/venv/lib/python3.12/site-packages/flask/app.py:1414]
Traceback (most recent call last):
  File "/Users/thanhvy/Documents/microblog/venv/lib/python3.12/site-packages/flask/app.py", line 2190, in wsgi_app
    response = self.full_dispatch_request()
               ^^^^^^^^^^^^^^^^^^^^^^^^^^^^
  File "/Users/thanhvy/Documents/microblog/venv/lib/python3.12/site-packages/flask/app.py", line 1486, in full_dispatch_request
    rv = self.handle_user_exception(e)
         ^^^^^^^^^^^^^^^^^^^^^^^^^^^^^
  File "/Users/thanhvy/Documents/microblog/venv/lib/python3.12/site-packages/flask/app.py", line 1484, in full_dispatch_request
    rv = self.dispatch_request()
         ^^^^^^^^^^^^^^^^^^^^^^^
  File "/Users/thanhvy/Documents/microblog/venv/lib/python3.12/site-packages/flask/app.py", line 1469, in dispatch_request
    return self.ensure_sync(self.view_functions[rule.endpoint])(**view_args)
           ^^^^^^^^^^^^^^^^^^^^^^^^^^^^^^^^^^^^^^^^^^^^^^^^^^^^^^^^^^^^^^^^^
  File "/Users/thanhvy/Documents/microblog/venv/lib/python3.12/site-packages/flask_httpauth.py", line 174, in decorated
    return self.ensure_sync(f)(*args, **kwargs)
           ^^^^^^^^^^^^^^^^^^^^^^^^^^^^^^^^^^^^
  File "/Users/thanhvy/Documents/microblog/app/api/users.py", line 12, in get_user
    return db.get_or_404(User, id).to_dict()
           ^^^^^^^^^^^^^^^^^^^^^^^^^^^^^^^^^
  File "/Users/thanhvy/Documents/microblog/app/models.py", line 268, in to_dict
    'post': url_for('api.get_post', id=self.id),
            ^^^^^^^^^^^^^^^^^^^^^^^^^^^^^^^^^^^
  File "/Users/thanhvy/Documents/microblog/venv/lib/python3.12/site-packages/flask/helpers.py", line 225, in url_for
    return current_app.url_for(
           ^^^^^^^^^^^^^^^^^^^^
  File "/Users/thanhvy/Documents/microblog/venv/lib/python3.12/site-packages/flask/app.py", line 1697, in url_for
    return self.handle_url_build_error(error, endpoint, values)
           ^^^^^^^^^^^^^^^^^^^^^^^^^^^^^^^^^^^^^^^^^^^^^^^^^^^^
  File "/Users/thanhvy/Documents/microblog/venv/lib/python3.12/site-packages/flask/app.py", line 1686, in url_for
    rv = url_adapter.build(  # type: ignore[union-attr]
         ^^^^^^^^^^^^^^^^^^^^^^^^^^^^^^^^^^^^^^^^^^^^^^
  File "/Users/thanhvy/Documents/microblog/venv/lib/python3.12/site-packages/werkzeug/routing/map.py", line 950, in build
    raise BuildError(endpoint, values, method, self)
werkzeug.routing.exceptions.BuildError: Could not build url for endpoint 'api.get_post' with values ['id']. Did you mean 'api.get_user' instead?
